 cout<<"did"<<std::endl;
  }

  catch (const std::exception & e) {
    std::cerr << "Error: " << e.what() << "\n";
    return (EXIT_FAILURE);
  }

  return (EXIT_SUCCESS);
}
